<sdf version='1.9'>
  <model name='pro_arm_6dof_900'>
    <joint name='pro_arm_base_joint' type='fixed'>
      <pose relative_to='__model__'>0 0 0 0 0 0</pose>
      <parent>world</parent>
      <child>pro_arm_base_link</child>
    </joint>
    <link name='pro_arm_base_link'>
      <pose relative_to='pro_arm_base_joint'>0 0 0 0 0 0</pose>
      <inertial>
        <pose>-1.0222e-11 0.011953 -2.0453e-11 0 0 0</pose>
        <mass>0.10000000000000001</mass>
        <inertia>
          <ixx>1.49364574483525e-05</ixx>
          <ixy>3.5429896300000001e-12</ixy>
          <ixz>-8.1927139999999995e-14</ixz>
          <iyy>1.49325665831382e-05</iyy>
          <iyz>-8.6239100000000001e-15</iyz>
          <izz>2.7023108518141601e-05</izz>
        </inertia>
      </inertial>
      <collision name='pro_arm_base_link_collision'>
        <pose>0 0 0 0 0 0</pose>
        <geometry>
          <mesh>
            <scale>1 1 1</scale>
            <uri>meshes_900/collision/pro_arm_base_link.STL</uri>
          </mesh>
        </geometry>
        <surface>
          <contact>
            <ode/>
          </contact>
          <friction>
            <ode>
              <mu>0.29999999999999999</mu>
              <mu2>0.29999999999999999</mu2>
            </ode>
          </friction>
        </surface>
      </collision>
      <visual name='pro_arm_base_link_visual'>
        <pose>0 0 0 0 0 0</pose>
        <geometry>
          <mesh>
            <scale>1 1 1</scale>
            <uri>meshes_900/visual/pro_arm_base_link.STL</uri>
          </mesh>
        </geometry>
        <material>
          <diffuse>0.941175 0.941175 0.941175 1</diffuse>
          <ambient>0.941175 0.941175 0.941175 1</ambient>
        </material>
      </visual>
    </link>
    <joint name='pro_arm_joint_1' type='revolute'>
      <pose relative_to='pro_arm_base_link'>0 0 0.042 -1.570792653576406 1.570792653605768 3.141592653589793</pose>
      <parent>pro_arm_base_link</parent>
      <child>pro_arm_link_1</child>
      <axis>
        <xyz>1 0 0</xyz>
        <limit>
          <lower>-3.1415926535897931</lower>
          <upper>3.1415926535897931</upper>
          <effort>130</effort>
          <velocity>1.5700000000000001</velocity>
        </limit>
        <dynamics>
          <damping>0.10000000000000001</damping>
          <friction>0.5</friction>
          <spring_reference>0</spring_reference>
          <spring_stiffness>0</spring_stiffness>
        </dynamics>
      </axis>
      <physics>
        <ode>
          <limit>
            <cfm>0</cfm>
            <erp>0.20000000000000001</erp>
          </limit>
        </ode>
      </physics>
    </joint>
    <link name='pro_arm_link_1'>
      <pose relative_to='pro_arm_joint_1'>0 0 0 0 0 0</pose>
      <inertial>
        <pose>-6.485469 3.6e-05 0.48748 0 0 0</pose>
        <mass>4.5</mass>
        <inertia>
          <ixx>0.0011757827156070599</ixx>
          <ixy>9.0157163991944899e-09</ixy>
          <ixz>1.41417369877024e-05</ixz>
          <iyy>0.0012730377288014899</iyy>
          <iyz>1.98305003772366e-09</iyz>
          <izz>0.0010756286628098399</izz>
        </inertia>
      </inertial>
      <collision name='pro_arm_link_1_collision'>
        <pose>0 0 0 0 0 0</pose>
        <geometry>
          <mesh>
            <scale>1 1 1</scale>
            <uri>meshes_900/collision/pro_arm_link_1.STL</uri>
          </mesh>
        </geometry>
        <surface>
          <contact>
            <ode/>
          </contact>
          <friction>
            <ode>
              <mu>0.29999999999999999</mu>
              <mu2>0.29999999999999999</mu2>
            </ode>
          </friction>
        </surface>
      </collision>
      <visual name='pro_arm_link_1_visual'>
        <pose>0 0 0 0 0 0</pose>
        <geometry>
          <mesh>
            <scale>1 1 1</scale>
            <uri>meshes_900/visual/pro_arm_link_1.STL</uri>
          </mesh>
        </geometry>
        <material>
          <diffuse>0.941175 0.941175 0.941175 1</diffuse>
          <ambient>0.941175 0.941175 0.941175 1</ambient>
        </material>
      </visual>
    </link>
    <joint name='pro_arm_joint_2' type='revolute'>
      <pose relative_to='pro_arm_link_1'>-0.075 0 -0.063583 1.172092653599064 1.570792653605768 2.270002653592138</pose>
      <parent>pro_arm_link_1</parent>
      <child>pro_arm_link_2</child>
      <axis>
        <xyz>1 0 0</xyz>
        <limit>
          <lower>-1.570796326794897</lower>
          <upper>1.570796326794897</upper>
          <effort>130</effort>
          <velocity>1.5700000000000001</velocity>
        </limit>
        <dynamics>
          <damping>0.10000000000000001</damping>
          <friction>0.5</friction>
          <spring_reference>0</spring_reference>
          <spring_stiffness>0</spring_stiffness>
        </dynamics>
      </axis>
      <physics>
        <ode>
          <limit>
            <cfm>0</cfm>
            <erp>0.20000000000000001</erp>
          </limit>
        </ode>
      </physics>
    </joint>
    <link name='pro_arm_link_2'>
      <pose relative_to='pro_arm_joint_2'>0 0 0 0 0 0</pose>
      <inertial>
        <pose>0.0826489985469987 0.115830980187337 -0.0588067754556333 0 0 0</pose>
        <mass>6</mass>
        <inertia>
          <ixx>0.0044665869776592598</ixx>
          <ixy>6.3642133012885001e-06</ixy>
          <ixz>-3.2469698364543102e-06</ixz>
          <iyy>0.0023754389914929499</iyy>
          <iyz>0.00085754001198963797</iyz>
          <izz>0.0036085135302251301</izz>
        </inertia>
      </inertial>
      <collision name='pro_arm_link_2_collision'>
        <pose>0 0 0 0 0 0</pose>
        <geometry>
          <mesh>
            <scale>1 1 1</scale>
            <uri>meshes_900/collision/pro_arm_link_2.STL</uri>
          </mesh>
        </geometry>
        <surface>
          <contact>
            <ode/>
          </contact>
          <friction>
            <ode>
              <mu>0.29999999999999999</mu>
              <mu2>0.29999999999999999</mu2>
            </ode>
          </friction>
        </surface>
      </collision>
      <visual name='pro_arm_link_2_visual'>
        <pose>0 0 0 0 0 0</pose>
        <geometry>
          <mesh>
            <scale>1 1 1</scale>
            <uri>meshes_900/visual/pro_arm_link_2.STL</uri>
          </mesh>
        </geometry>
        <material>
          <diffuse>0.941175 0.941175 0.941175 1</diffuse>
          <ambient>0.941175 0.941175 0.941175 1</ambient>
        </material>
      </visual>
    </link>
    <joint name='pro_arm_joint_3' type='revolute'>
      <pose relative_to='pro_arm_link_2'>0 0.36722 -0.18789 0.3124799999999999 0 0</pose>
      <parent>pro_arm_link_2</parent>
      <child>pro_arm_link_3</child>
      <axis>
        <xyz>1 0 0</xyz>
        <limit>
          <lower>-2.0943951023931948</lower>
          <upper>2.0943951023931948</upper>
          <effort>54</effort>
          <velocity>0.78539999999999999</velocity>
        </limit>
        <dynamics>
          <damping>0.10000000000000001</damping>
          <friction>0.5</friction>
          <spring_reference>0</spring_reference>
          <spring_stiffness>0</spring_stiffness>
        </dynamics>
      </axis>
      <physics>
        <ode>
          <limit>
            <cfm>0</cfm>
            <erp>0.20000000000000001</erp>
          </limit>
        </ode>
      </physics>
    </joint>
    <link name='pro_arm_link_3'>
      <pose relative_to='pro_arm_joint_3'>0 0 0 0 0 0</pose>
      <inertial>
        <pose>0.00457820497425972 -0.0013810445300742 0.00139637649876129 0 0 0</pose>
        <mass>1.52</mass>
        <inertia>
          <ixx>0.00023312085297372799</ixx>
          <ixy>-9.9105717103588105e-07</ixy>
          <ixz>9.2819911026509899e-07</ixz>
          <iyy>0.00018327742188443399</iyy>
          <iyz>-8.4324713389597698e-06</iyz>
          <izz>0.00018278514588324001</izz>
        </inertia>
      </inertial>
      <collision name='pro_arm_link_3_collision'>
        <pose>0 0 0 0 0 0</pose>
        <geometry>
          <mesh>
            <scale>1 1 1</scale>
            <uri>meshes_900/collision/pro_arm_link_3.STL</uri>
          </mesh>
        </geometry>
        <surface>
          <contact>
            <ode/>
          </contact>
          <friction>
            <ode>
              <mu>0.29999999999999999</mu>
              <mu2>0.29999999999999999</mu2>
            </ode>
          </friction>
        </surface>
      </collision>
      <visual name='pro_arm_link_3_visual'>
        <pose>0 0 0 0 0 0</pose>
        <geometry>
          <mesh>
            <scale>1 1 1</scale>
            <uri>meshes_900/visual/pro_arm_link_3.STL</uri>
          </mesh>
        </geometry>
        <material>
          <diffuse>0.941175 0.941175 0.941175 1</diffuse>
          <ambient>0.941175 0.941175 0.941175 1</ambient>
        </material>
      </visual>
    </link>
    <joint name='pro_arm_joint_4' type='revolute'>
      <pose relative_to='pro_arm_link_3'>-0.024583 0.0026942 -0.0026942 0 0 0</pose>
      <parent>pro_arm_link_3</parent>
      <child>pro_arm_link_4</child>
      <axis>
        <xyz>0 0.70711 -0.70711</xyz>
        <limit>
          <lower>-3.1415926535897931</lower>
          <upper>3.1415926535897931</upper>
          <effort>54</effort>
          <velocity>0.78539999999999999</velocity>
        </limit>
        <dynamics>
          <damping>0.10000000000000001</damping>
          <friction>0.5</friction>
          <spring_reference>0</spring_reference>
          <spring_stiffness>0</spring_stiffness>
        </dynamics>
      </axis>
      <physics>
        <ode>
          <limit>
            <cfm>0</cfm>
            <erp>0.20000000000000001</erp>
          </limit>
        </ode>
      </physics>
    </joint>
    <link name='pro_arm_link_4'>
      <pose relative_to='pro_arm_joint_4'>0 0 0 0 0 0</pose>
      <inertial>
        <pose>9.60265339091521e-05 0.165003016703847 -0.164764525095486 0 0 0</pose>
        <mass>1.52</mass>
        <inertia>
          <ixx>0.0030029962461123301</ixx>
          <ixy>9.13978026360818e-07</ixy>
          <ixz>-8.77916805572091e-07</ixz>
          <iyy>0.0019034991115768</iyy>
          <iyz>0.0010789570297446299</iyz>
          <izz>0.00190344015518851</izz>
        </inertia>
      </inertial>
      <collision name='pro_arm_link_4_collision'>
        <pose>0 0 0 0 0 0</pose>
        <geometry>
          <mesh>
            <scale>1 1 1</scale>
            <uri>meshes_900/collision/pro_arm_link_4.STL</uri>
          </mesh>
        </geometry>
        <surface>
          <contact>
            <ode/>
          </contact>
          <friction>
            <ode>
              <mu>0.29999999999999999</mu>
              <mu2>0.29999999999999999</mu2>
            </ode>
          </friction>
        </surface>
      </collision>
      <visual name='pro_arm_link_4_visual'>
        <pose>0 0 0 0 0 0</pose>
        <geometry>
          <mesh>
            <scale>1 1 1</scale>
            <uri>meshes_900/visual/pro_arm_link_4.STL</uri>
          </mesh>
        </geometry>
        <material>
          <diffuse>0.941175 0.941175 0.941175 1</diffuse>
          <ambient>0.941175 0.941175 0.941175 1</ambient>
        </material>
      </visual>
    </link>
    <joint name='pro_arm_joint_5' type='revolute'>
      <pose relative_to='pro_arm_link_4'>0.048 0.28828 -0.28828 -0.7854000000000001 0 0</pose>
      <parent>pro_arm_link_4</parent>
      <child>pro_arm_link_5</child>
      <axis>
        <xyz>1 0 0</xyz>
        <limit>
          <lower>-3.1415926535897931</lower>
          <upper>3.1415926535897931</upper>
          <effort>19</effort>
          <velocity>0.78539999999999999</velocity>
        </limit>
        <dynamics>
          <damping>0.10000000000000001</damping>
          <friction>0.5</friction>
          <spring_reference>0</spring_reference>
          <spring_stiffness>0</spring_stiffness>
        </dynamics>
      </axis>
      <physics>
        <ode>
          <limit>
            <cfm>0</cfm>
            <erp>0.20000000000000001</erp>
          </limit>
        </ode>
      </physics>
    </joint>
    <link name='pro_arm_link_5'>
      <pose relative_to='pro_arm_joint_5'>0 0 0 0 0 0</pose>
      <inertial>
        <pose>0.0449928461965346 -0.000256793176622971 4.79955057997106e-05 0 0 0</pose>
        <mass>1.1000000000000001</mass>
        <inertia>
          <ixx>0.00024826391825770401</ixx>
          <ixy>-1.26708446953254e-06</ixy>
          <ixz>2.83208766882495e-08</ixz>
          <iyy>0.000198829511118026</iyy>
          <iyz>1.04647409519695e-07</iyz>
          <izz>0.000183426745229536</izz>
        </inertia>
      </inertial>
      <collision name='pro_arm_link_5_collision'>
        <pose>0 0 0 0 0 0</pose>
        <geometry>
          <mesh>
            <scale>1 1 1</scale>
            <uri>meshes_900/collision/pro_arm_link_5.STL</uri>
          </mesh>
        </geometry>
        <surface>
          <contact>
            <ode/>
          </contact>
          <friction>
            <ode>
              <mu>0.29999999999999999</mu>
              <mu2>0.29999999999999999</mu2>
            </ode>
          </friction>
        </surface>
      </collision>
      <visual name='pro_arm_link_5_visual'>
        <pose>0 0 0 0 0 0</pose>
        <geometry>
          <mesh>
            <scale>1 1 1</scale>
            <uri>meshes_900/visual/pro_arm_link_5.STL</uri>
          </mesh>
        </geometry>
        <material>
          <diffuse>0.941175 0.941175 0.941175 1</diffuse>
          <ambient>0.941175 0.941175 0.941175 1</ambient>
        </material>
      </visual>
    </link>
    <joint name='pro_arm_joint_6' type='revolute'>
      <pose relative_to='pro_arm_link_5'>0.076 -0.048 0 -3.141585307179587 -1.545400000000002 -3.141585307179587</pose>
      <parent>pro_arm_link_5</parent>
      <child>pro_arm_link_6</child>
      <axis>
        <xyz>0 1 0</xyz>
        <limit>
          <lower>-3.1415926535897931</lower>
          <upper>3.1415926535897931</upper>
          <effort>19</effort>
          <velocity>0.78539999999999999</velocity>
        </limit>
        <dynamics>
          <damping>0.10000000000000001</damping>
          <friction>0.5</friction>
          <spring_reference>0</spring_reference>
          <spring_stiffness>0</spring_stiffness>
        </dynamics>
      </axis>
      <physics>
        <ode>
          <limit>
            <cfm>0</cfm>
            <erp>0.20000000000000001</erp>
          </limit>
        </ode>
      </physics>
    </joint>
    <link name='pro_arm_link_6'>
      <pose relative_to='pro_arm_joint_6'>0 0 0 0 0 0</pose>
      <inertial>
        <pose>3.83807569059869e-15 -0.0125000000000002 0.000195763682872163 0 0 0</pose>
        <mass>0.080000000000000002</mass>
        <inertia>
          <ixx>5.4307489272127899e-05</ixx>
          <ixy>-8.4166960395035794e-21</ixy>
          <ixz>1.35169517722841e-17</ixz>
          <iyy>0.000100760354633415</iyy>
          <iyz>1.3098385758206299e-21</iyz>
          <izz>5.4873397232815998e-05</izz>
        </inertia>
      </inertial>
      <collision name='pro_arm_link_6_collision'>
        <pose>0 0 0 0 0 0</pose>
        <geometry>
          <mesh>
            <scale>1 1 1</scale>
            <uri>meshes_900/collision/pro_arm_link_6.STL</uri>
          </mesh>
        </geometry>
        <surface>
          <contact>
            <ode/>
          </contact>
          <friction>
            <ode>
              <mu>0.29999999999999999</mu>
              <mu2>0.29999999999999999</mu2>
            </ode>
          </friction>
        </surface>
      </collision>
      <visual name='pro_arm_link_6_visual'>
        <pose>0 0 0 0 0 0</pose>
        <geometry>
          <mesh>
            <scale>1 1 1</scale>
            <uri>meshes_900/visual/pro_arm_link_6.STL</uri>
          </mesh>
        </geometry>
        <material>
          <diffuse>0.941175 0.941175 0.941175 1</diffuse>
          <ambient>0.941175 0.941175 0.941175 1</ambient>
        </material>
      </visual>
    </link>
    <plugin name='ign_ros2_control::IgnitionROS2ControlPlugin' filename='ign_ros2_control-system'>
      <parameters>/home/geraldinebc/Documents/GIT/local_pro_tests/install/pro_arm_moveit/share/pro_arm_moveit/config/controllers_6dof.yaml</parameters>
    </plugin>
    <frame name='pro_arm_ee_virtual_joint' attached_to='pro_arm_link_6'>
      <pose>0 -0.025 0 0 -0 0</pose>
    </frame>
    <frame name='pro_arm_ee' attached_to='pro_arm_ee_virtual_joint'/>
  </model>
</sdf>
