<sdf version='1.9'>
  <model name='pro_arm_6dof_550'>
    <joint name='pro_arm_base_joint' type='fixed'>
      <pose relative_to='__model__'>0 0 0 0 0 0</pose>
      <parent>world</parent>
      <child>pro_arm_base_link</child>
    </joint>
    <link name='pro_arm_base_link'>
      <pose relative_to='pro_arm_base_joint'>0 0 0 0 0 0</pose>
      <inertial>
        <pose>0 0 0.015 0 0 0</pose>
        <mass>1</mass>
        <inertia>
          <ixx>0.00083597468313530805</ixx>
          <ixy>6.2680200136281394e-08</ixy>
          <ixz>1.59119110825247e-12</ixz>
          <iyy>0.00083590941937120901</iyy>
          <iyz>5.3039703608415704e-13</iyz>
          <izz>0.00147373548763275</izz>
        </inertia>
      </inertial>
      <collision name='pro_arm_base_link_collision'>
        <pose>0 0 0 0 0 0</pose>
        <geometry>
          <mesh>
            <scale>1 1 1</scale>
            <uri>meshes_550/collision/pro_arm_base_link.STL</uri>
          </mesh>
        </geometry>
        <surface>
          <contact>
            <ode/>
          </contact>
          <friction>
            <ode>
              <mu>0.29999999999999999</mu>
              <mu2>0.29999999999999999</mu2>
            </ode>
          </friction>
        </surface>
      </collision>
      <visual name='pro_arm_base_link_visual'>
        <pose>0 0 0 0 0 0</pose>
        <geometry>
          <mesh>
            <scale>1 1 1</scale>
            <uri>meshes_550/visual/pro_arm_base_link.STL</uri>
          </mesh>
        </geometry>
        <material>
          <diffuse>0.941175 0.941175 0.941175 1</diffuse>
          <ambient>0.941175 0.941175 0.941175 1</ambient>
        </material>
      </visual>
    </link>
    <joint name='pro_arm_joint_1' type='revolute'>
      <pose relative_to='pro_arm_base_link'>0 0 0.0315 -1.570792653576406 1.570792653605768 3.141592653589793</pose>
      <parent>pro_arm_base_link</parent>
      <child>pro_arm_link_1</child>
      <axis>
        <xyz>1 0 0</xyz>
        <limit>
          <lower>-3.1415926535897931</lower>
          <upper>3.1415926535897931</upper>
          <effort>54</effort>
          <velocity>0.78539999999999999</velocity>
        </limit>
        <dynamics>
          <damping>0.10000000000000001</damping>
          <friction>0.5</friction>
          <spring_reference>0</spring_reference>
          <spring_stiffness>0</spring_stiffness>
        </dynamics>
      </axis>
      <physics>
        <ode>
          <limit>
            <cfm>0</cfm>
            <erp>0.20000000000000001</erp>
          </limit>
        </ode>
      </physics>
    </joint>
    <link name='pro_arm_link_1'>
      <pose relative_to='pro_arm_joint_1'>0 0 0 0 0 0</pose>
      <inertial>
        <pose>-0.04167 -4.7565e-05 0.00324 0 0 0</pose>
        <mass>1.52</mass>
        <inertia>
          <ixx>0.00014346000000000001</ixx>
          <ixy>-4.3176999999999997e-08</ixy>
          <ixz>1.3566000000000001e-06</ixz>
          <iyy>0.00012596999999999999</iyy>
          <iyz>-1.5203999999999998e-08</iyz>
          <izz>0.00014254</izz>
        </inertia>
      </inertial>
      <collision name='pro_arm_link_1_collision'>
        <pose>0 0 0 0 0 0</pose>
        <geometry>
          <mesh>
            <scale>1 1 1</scale>
            <uri>meshes_550/collision/pro_arm_link_1.STL</uri>
          </mesh>
        </geometry>
        <surface>
          <contact>
            <ode/>
          </contact>
          <friction>
            <ode>
              <mu>0.29999999999999999</mu>
              <mu2>0.29999999999999999</mu2>
            </ode>
          </friction>
        </surface>
      </collision>
      <visual name='pro_arm_link_1_visual'>
        <pose>0 0 0 0 0 0</pose>
        <geometry>
          <mesh>
            <scale>1 1 1</scale>
            <uri>meshes_550/visual/pro_arm_link_1.STL</uri>
          </mesh>
        </geometry>
        <material>
          <diffuse>0.941175 0.941175 0.941175 1</diffuse>
          <ambient>0.941175 0.941175 0.941175 1</ambient>
        </material>
      </visual>
    </link>
    <joint name='pro_arm_joint_2' type='revolute'>
      <pose relative_to='pro_arm_link_1'>-0.05 0 -0.045583 -2.356192653568856 1.570792653635993 -1.570792653561293</pose>
      <parent>pro_arm_link_1</parent>
      <child>pro_arm_link_2</child>
      <axis>
        <xyz>1 0 0</xyz>
        <limit>
          <lower>-1.570796326794897</lower>
          <upper>1.570796326794897</upper>
          <effort>54</effort>
          <velocity>0.78539999999999999</velocity>
        </limit>
        <dynamics>
          <damping>0.10000000000000001</damping>
          <friction>0.5</friction>
          <spring_reference>0</spring_reference>
          <spring_stiffness>0</spring_stiffness>
        </dynamics>
      </axis>
      <physics>
        <ode>
          <limit>
            <cfm>0</cfm>
            <erp>0.20000000000000001</erp>
          </limit>
        </ode>
      </physics>
    </joint>
    <link name='pro_arm_link_2'>
      <pose relative_to='pro_arm_joint_2'>0 0 0 0 0 0</pose>
      <inertial>
        <pose>0.11278 0.068036 -0.06789100000000001 0 0 0</pose>
        <mass>3.1000000000000001</mass>
        <inertia>
          <ixx>0.00069567999999999995</ixx>
          <ixy>-1.3919000000000001e-10</ixy>
          <ixz>-4.9213000000000004e-10</ixz>
          <iyy>0.00059931000000000003</iyy>
          <iyz>1.5313999999999999e-05</iyz>
          <izz>0.00059896999999999999</izz>
        </inertia>
      </inertial>
      <collision name='pro_arm_link_2_collision'>
        <pose>0 0 0 0 0 0</pose>
        <geometry>
          <mesh>
            <scale>1 1 1</scale>
            <uri>meshes_550/collision/pro_arm_link_2.STL</uri>
          </mesh>
        </geometry>
        <surface>
          <contact>
            <ode/>
          </contact>
          <friction>
            <ode>
              <mu>0.29999999999999999</mu>
              <mu2>0.29999999999999999</mu2>
            </ode>
          </friction>
        </surface>
      </collision>
      <visual name='pro_arm_link_2_visual'>
        <pose>0 0 0 0 0 0</pose>
        <geometry>
          <mesh>
            <scale>1 1 1</scale>
            <uri>meshes_550/visual/pro_arm_link_2.STL</uri>
          </mesh>
        </geometry>
        <material>
          <diffuse>0.941175 0.941175 0.941175 1</diffuse>
          <ambient>0.941175 0.941175 0.941175 1</ambient>
        </material>
      </visual>
    </link>
    <joint name='pro_arm_joint_3' type='revolute'>
      <pose relative_to='pro_arm_link_2'>0 0.1591 -0.1591 1.5511 0 0</pose>
      <parent>pro_arm_link_2</parent>
      <child>pro_arm_link_3</child>
      <axis>
        <xyz>1 0 0</xyz>
        <limit>
          <lower>-2.0943951023931948</lower>
          <upper>2.0943951023931948</upper>
          <effort>54</effort>
          <velocity>0.78539999999999999</velocity>
        </limit>
        <dynamics>
          <damping>0.10000000000000001</damping>
          <friction>0.5</friction>
          <spring_reference>0</spring_reference>
          <spring_stiffness>0</spring_stiffness>
        </dynamics>
      </axis>
      <physics>
        <ode>
          <limit>
            <cfm>0</cfm>
            <erp>0.20000000000000001</erp>
          </limit>
        </ode>
      </physics>
    </joint>
    <link name='pro_arm_link_3'>
      <pose relative_to='pro_arm_joint_3'>0 0 0 0 0 0</pose>
      <inertial>
        <pose>0.025163 -0.0013073 -0.0014894 0 0 0</pose>
        <mass>1.52</mass>
        <inertia>
          <ixx>0.00023311999999999999</ixx>
          <ixy>-9.0841000000000002e-07</ixy>
          <ixz>-1.0076000000000001e-06</ixz>
          <iyy>0.00018296999999999999</iyy>
          <iyz>8.2632999999999993e-06</iyz>
          <izz>0.00018310000000000001</izz>
        </inertia>
      </inertial>
      <collision name='pro_arm_link_3_collision'>
        <pose>0 0 0 0 0 0</pose>
        <geometry>
          <mesh>
            <scale>1 1 1</scale>
            <uri>meshes_550/collision/pro_arm_link_3.STL</uri>
          </mesh>
        </geometry>
        <surface>
          <contact>
            <ode/>
          </contact>
          <friction>
            <ode>
              <mu>0.29999999999999999</mu>
              <mu2>0.29999999999999999</mu2>
            </ode>
          </friction>
        </surface>
      </collision>
      <visual name='pro_arm_link_3_visual'>
        <pose>0 0 0 0 0 0</pose>
        <geometry>
          <mesh>
            <scale>1 1 1</scale>
            <uri>meshes_550/visual/pro_arm_link_3.STL</uri>
          </mesh>
        </geometry>
        <material>
          <diffuse>0.941175 0.941175 0.941175 1</diffuse>
          <ambient>0.941175 0.941175 0.941175 1</ambient>
        </material>
      </visual>
    </link>
    <joint name='pro_arm_joint_4' type='revolute'>
      <pose relative_to='pro_arm_link_3'>-0.05 0 0 0 0 0</pose>
      <parent>pro_arm_link_3</parent>
      <child>pro_arm_link_4</child>
      <axis>
        <xyz>0 0.69305 0.72089</xyz>
        <limit>
          <lower>-3.1415926535897931</lower>
          <upper>3.1415926535897931</upper>
          <effort>19</effort>
          <velocity>0.78539999999999999</velocity>
        </limit>
        <dynamics>
          <damping>0.10000000000000001</damping>
          <friction>0.5</friction>
          <spring_reference>0</spring_reference>
          <spring_stiffness>0</spring_stiffness>
        </dynamics>
      </axis>
      <physics>
        <ode>
          <limit>
            <cfm>0</cfm>
            <erp>0.20000000000000001</erp>
          </limit>
        </ode>
      </physics>
    </joint>
    <link name='pro_arm_link_4'>
      <pose relative_to='pro_arm_joint_4'>0 0 0 0 0 0</pose>
      <inertial>
        <pose>-0.0038418 0.10849 0.11305 0 0 0</pose>
        <mass>1.2</mass>
        <inertia>
          <ixx>0.00051393999999999995</ixx>
          <ixy>8.5873999999999997e-07</ixy>
          <ixz>9.3147999999999997e-07</ixz>
          <iyy>0.00048842000000000004</iyy>
          <iyz>-3.1317999999999998e-06</iyz>
          <izz>0.00048822999999999998</izz>
        </inertia>
      </inertial>
      <collision name='pro_arm_link_4_collision'>
        <pose>0 0 0 0 0 0</pose>
        <geometry>
          <mesh>
            <scale>1 1 1</scale>
            <uri>meshes_550/collision/pro_arm_link_4.STL</uri>
          </mesh>
        </geometry>
        <surface>
          <contact>
            <ode/>
          </contact>
          <friction>
            <ode>
              <mu>0.29999999999999999</mu>
              <mu2>0.29999999999999999</mu2>
            </ode>
          </friction>
        </surface>
      </collision>
      <visual name='pro_arm_link_4_visual'>
        <pose>0 0 0 0 0 0</pose>
        <geometry>
          <mesh>
            <scale>1 1 1</scale>
            <uri>meshes_550/visual/pro_arm_link_4.STL</uri>
          </mesh>
        </geometry>
        <material>
          <diffuse>0.941175 0.941175 0.941175 1</diffuse>
          <ambient>0.941175 0.941175 0.941175 1</ambient>
        </material>
      </visual>
    </link>
    <joint name='pro_arm_joint_5' type='revolute'>
      <pose relative_to='pro_arm_link_4'>0.048417 -0.17257 -0.1795 0.80509 0 0</pose>
      <parent>pro_arm_link_4</parent>
      <child>pro_arm_link_5</child>
      <axis>
        <xyz>1 0 0</xyz>
        <limit>
          <lower>-3.1415926535897931</lower>
          <upper>3.1415926535897931</upper>
          <effort>19</effort>
          <velocity>0.78539999999999999</velocity>
        </limit>
        <dynamics>
          <damping>0.10000000000000001</damping>
          <friction>0.5</friction>
          <spring_reference>0</spring_reference>
          <spring_stiffness>0</spring_stiffness>
        </dynamics>
      </axis>
      <physics>
        <ode>
          <limit>
            <cfm>0</cfm>
            <erp>0.20000000000000001</erp>
          </limit>
        </ode>
      </physics>
    </joint>
    <link name='pro_arm_link_5'>
      <pose relative_to='pro_arm_joint_5'>0 0 0 0 0 0</pose>
      <inertial>
        <pose>-0.0057446 1 -3.2832e-05 0 0 0</pose>
        <mass>1.1000000000000001</mass>
        <inertia>
          <ixx>0.00024824999999999999</ixx>
          <ixy>-1.2711e-06</ixy>
          <ixz>3.0302999999999997e-08</ixz>
          <iyy>0.00019935999999999999</iyy>
          <iyz>-3.9256999999999999e-08</iyz>
          <izz>0.00018289000000000001</izz>
        </inertia>
      </inertial>
      <collision name='pro_arm_link_5_collision'>
        <pose>0 0 0 0 0 0</pose>
        <geometry>
          <mesh>
            <scale>1 1 1</scale>
            <uri>meshes_550/collision/pro_arm_link_5.STL</uri>
          </mesh>
        </geometry>
        <surface>
          <contact>
            <ode/>
          </contact>
          <friction>
            <ode>
              <mu>0.29999999999999999</mu>
              <mu2>0.29999999999999999</mu2>
            </ode>
          </friction>
        </surface>
      </collision>
      <visual name='pro_arm_link_5_visual'>
        <pose>0 0 0 0 0 0</pose>
        <geometry>
          <mesh>
            <scale>1 1 1</scale>
            <uri>meshes_550/visual/pro_arm_link_5.STL</uri>
          </mesh>
        </geometry>
        <material>
          <diffuse>0.941175 0.941175 0.941175 1</diffuse>
          <ambient>0.941175 0.941175 0.941175 1</ambient>
        </material>
      </visual>
    </link>
    <joint name='pro_arm_joint_6' type='revolute'>
      <pose relative_to='pro_arm_link_5'>0.076 0.048 0 -1.570792653617749 1.570792653666219 -1.570792653625737</pose>
      <parent>pro_arm_link_5</parent>
      <child>pro_arm_link_6</child>
      <axis>
        <xyz>0 1 0</xyz>
        <limit>
          <lower>-3.1415926535897931</lower>
          <upper>3.1415926535897931</upper>
          <effort>19</effort>
          <velocity>0.78539999999999999</velocity>
        </limit>
        <dynamics>
          <damping>0.10000000000000001</damping>
          <friction>0.5</friction>
          <spring_reference>0</spring_reference>
          <spring_stiffness>0</spring_stiffness>
        </dynamics>
      </axis>
      <physics>
        <ode>
          <limit>
            <cfm>0</cfm>
            <erp>0.20000000000000001</erp>
          </limit>
        </ode>
      </physics>
    </joint>
    <link name='pro_arm_link_6'>
      <pose relative_to='pro_arm_joint_6'>0 0 0 0 0 0</pose>
      <inertial>
        <pose>3.5805e-15 0.0125 0.00019576 0 0 0</pose>
        <mass>0.080000000000000002</mass>
        <inertia>
          <ixx>5.4307e-05</ixx>
          <ixy>-1.1438e-20</ixy>
          <ixz>1.3528999999999999e-17</ixz>
          <iyy>0.00010076</iyy>
          <iyz>-1.6647999999999999e-22</iyz>
          <izz>5.4873000000000001e-05</izz>
        </inertia>
      </inertial>
      <collision name='pro_arm_link_6_collision'>
        <pose>0 0 0 0 0 0</pose>
        <geometry>
          <mesh>
            <scale>1 1 1</scale>
            <uri>meshes_550/collision/pro_arm_link_6.STL</uri>
          </mesh>
        </geometry>
        <surface>
          <contact>
            <ode/>
          </contact>
          <friction>
            <ode>
              <mu>0.29999999999999999</mu>
              <mu2>0.29999999999999999</mu2>
            </ode>
          </friction>
        </surface>
      </collision>
      <visual name='pro_arm_link_6_visual'>
        <pose>0 0 0 0 0 0</pose>
        <geometry>
          <mesh>
            <scale>1 1 1</scale>
            <uri>meshes_550/visual/pro_arm_link_6.STL</uri>
          </mesh>
        </geometry>
        <material>
          <diffuse>0.941175 0.941175 0.941175 1</diffuse>
          <ambient>0.941175 0.941175 0.941175 1</ambient>
        </material>
      </visual>
    </link>
    <plugin name='ign_ros2_control::IgnitionROS2ControlPlugin' filename='ign_ros2_control-system'>
      <parameters>/home/geraldinebc/Documents/GIT/local_pro_tests/install/pro_arm_moveit/share/pro_arm_moveit/config/controllers_6dof.yaml</parameters>
    </plugin>
    <frame name='pro_arm_ee_virtual_joint' attached_to='pro_arm_link_6'>
      <pose>0 0.025 0 0 -0 0</pose>
    </frame>
    <frame name='pro_arm_ee' attached_to='pro_arm_ee_virtual_joint'/>
  </model>
</sdf>
